<sdf version='1.6'>
  <model name='movo'>
    <link name='linear_actuator_link'>
      <pose frame=''>0 0 0 0 -0 0</pose>
      <inertial>
        <pose frame=''>0.057144 -0.133204 0.279994 0 -0 0</pose>
        <mass>0.649618</mass>
        <inertia>
          <ixx>0.00048</ixx>
          <ixy>-1e-06</ixy>
          <ixz>-2.97953e-13</ixz>
          <iyy>0.000652</iyy>
          <iyz>-1.79717e-15</iyz>
          <izz>0.000646</izz>
        </inertia>
      </inertial>
      <collision name='linear_actuator_link_fixed_joint_lump__right_base_link_collision'>
        <pose frame=''>0.026105 -0.13335 0.279994 -1.5708 -0 -1.5708</pose>
        <geometry>
          <mesh>
            <scale>1 1 1</scale>
            <uri>model://movo_description/meshes/manipulation/jaco/collision/base.stl</uri>
          </mesh>
        </geometry>
        <surface>
          <contact>
            <ode>
              <kp>1e+06</kp>
              <kd>100</kd>
              <max_vel>100</max_vel>
              <min_depth>0.001</min_depth>
            </ode>
          </contact>
          <friction>
            <ode>
              <mu>1</mu>
              <mu2>1</mu2>
            </ode>
          </friction>
        </surface>
      </collision>
      <visual name='linear_actuator_link_fixed_joint_lump__right_base_link_visual'>
        <pose frame=''>0.026105 -0.13335 0.279994 -1.5708 -0 -1.5708</pose>
        <geometry>
          <mesh>
            <scale>1 1 1</scale>
            <uri>model://movo_description/meshes/manipulation/jaco/visual/base.dae</uri>
          </mesh>
        </geometry>
        <material>
          <script>
            <uri>__default__</uri>
            <name>__default__</name>
          </script>
        </material>
      </visual>
      <gravity>1</gravity>
      <velocity_decay/>
      <self_collide>0</self_collide>
    </link>
    <link name='right_shoulder_link'>
      <pose frame=''>0.088605 -0.13335 0.279994 -1.5708 0 1.5708</pose>
      <inertial>
        <pose frame=''>1.8e-05 -0.004667 -0.060609 0 -0 0</pose>
        <mass>0.824524</mass>
        <inertia>
          <ixx>0.002561</ixx>
          <ixy>0</ixy>
          <ixz>1e-06</ixz>
          <iyy>0.002653</iyy>
          <iyz>0.000212</iyz>
          <izz>0.000524</izz>
        </inertia>
      </inertial>
      <collision name='right_shoulder_link_collision'>
        <pose frame=''>0 0 0 0 -0 0</pose>
        <geometry>
          <mesh>
            <scale>1 1 1</scale>
            <uri>model://movo_description/meshes/manipulation/jaco/collision/shoulder_7dof.stl</uri>
          </mesh>
        </geometry>
        <surface>
          <contact>
            <ode>
              <kp>1e+06</kp>
              <kd>100</kd>
              <max_vel>100</max_vel>
              <min_depth>0.001</min_depth>
            </ode>
          </contact>
          <friction>
            <ode>
              <mu>1</mu>
              <mu2>1</mu2>
            </ode>
          </friction>
        </surface>
      </collision>
      <visual name='right_shoulder_link_visual'>
        <pose frame=''>0 0 0 0 -0 0</pose>
        <geometry>
          <mesh>
            <scale>1 1 1</scale>
            <uri>model://movo_description/meshes/manipulation/jaco/visual/shoulder_7dof.dae</uri>
          </mesh>
        </geometry>
        <material>
          <script>
            <uri>__default__</uri>
            <name>__default__</name>
          </script>
        </material>
      </visual>
      <gravity>1</gravity>
      <velocity_decay/>
      <self_collide>0</self_collide>
    </link>
    <joint name='right_shoulder_pan_joint' type='revolute'>
      <child>right_shoulder_link</child>
      <parent>linear_actuator_link</parent>
      <axis>
        <xyz>-1 -0 -0</xyz>
        <limit>
          <lower>-3.14159</lower>
          <upper>3.14159</upper>
          <effort>18000</effort>
          <velocity>0.69115</velocity>
        </limit>
        <dynamics>
          <damping>0.01</damping>
          <friction>0</friction>
          <spring_reference>0</spring_reference>
          <spring_stiffness>0</spring_stiffness>
        </dynamics>
        <use_parent_model_frame>1</use_parent_model_frame>
      </axis>
    </joint>
    <link name='right_arm_half_1_link'>
      <pose frame=''>0.207355 -0.13335 0.279994 -0 0 1.5708</pose>
      <inertial>
        <pose frame=''>0 -0.103563 0 0 -0 0</pose>
        <mass>0.8447</mass>
        <inertia>
          <ixx>0.000435</ixx>
          <ixy>2e-06</ixy>
          <ixz>0.000231</ixz>
          <iyy>0.034947</iyy>
          <iyz>0</iyz>
          <izz>0.035198</izz>
        </inertia>
      </inertial>
      <collision name='right_arm_half_1_link_collision'>
        <pose frame=''>0 0 0 0 -0 0</pose>
        <geometry>
          <mesh>
            <scale>1 1 1</scale>
            <uri>model://movo_description/meshes/manipulation/jaco/collision/arm_half_1.stl</uri>
          </mesh>
        </geometry>
        <surface>
          <contact>
            <ode>
              <kp>1e+06</kp>
              <kd>100</kd>
              <max_vel>100</max_vel>
              <min_depth>0.001</min_depth>
            </ode>
          </contact>
          <friction>
            <ode>
              <mu>1</mu>
              <mu2>1</mu2>
            </ode>
          </friction>
        </surface>
      </collision>
      <visual name='right_arm_half_1_link_visual'>
        <pose frame=''>0 0 0 0 -0 0</pose>
        <geometry>
          <mesh>
            <scale>1 1 1</scale>
            <uri>model://movo_description/meshes/manipulation/jaco/visual/arm_half_1.dae</uri>
          </mesh>
        </geometry>
        <material>
          <script>
            <uri>__default__</uri>
            <name>__default__</name>
          </script>
        </material>
      </visual>
      <gravity>1</gravity>
      <velocity_decay/>
      <self_collide>0</self_collide>
    </link>
    <joint name='right_shoulder_lift_joint' type='revolute'>
      <child>right_arm_half_1_link</child>
      <parent>right_shoulder_link</parent>
      <axis>
        <xyz>-0 0 1</xyz>
        <limit>
          <lower>-2.238</lower>
          <upper>2.238</upper>
          <effort>30000.5</effort>
          <velocity>0.69115</velocity>
        </limit>
        <dynamics>
          <damping>0.01</damping>
          <friction>0</friction>
          <spring_reference>0</spring_reference>
          <spring_stiffness>0</spring_stiffness>
        </dynamics>
        <use_parent_model_frame>1</use_parent_model_frame>
      </axis>
    </joint>
    <link name='right_arm_half_2_link'>
      <pose frame=''>0.412355 -0.13335 0.279994 -1.5708 0 1.5708</pose>
      <inertial>
        <pose frame=''>0 0 -0.102245 0 -0 0</pose>
        <mass>0.8447</mass>
        <inertia>
          <ixx>0.000435</ixx>
          <ixy>2e-06</ixy>
          <ixz>0.000231</ixz>
          <iyy>0.034947</iyy>
          <iyz>0</iyz>
          <izz>0.035198</izz>
        </inertia>
      </inertial>
      <collision name='right_arm_half_2_link_collision'>
        <pose frame=''>0 0 0 0 -0 0</pose>
        <geometry>
          <mesh>
            <scale>1 1 1</scale>
            <uri>model://movo_description/meshes/manipulation/jaco/collision/arm_half_2.stl</uri>
          </mesh>
        </geometry>
        <surface>
          <contact>
            <ode>
              <kp>1e+06</kp>
              <kd>100</kd>
              <max_vel>100</max_vel>
              <min_depth>0.001</min_depth>
            </ode>
          </contact>
          <friction>
            <ode>
              <mu>1</mu>
              <mu2>1</mu2>
            </ode>
          </friction>
        </surface>
      </collision>
      <visual name='right_arm_half_2_link_visual'>
        <pose frame=''>0 0 0 0 -0 0</pose>
        <geometry>
          <mesh>
            <scale>1 1 1</scale>
            <uri>model://movo_description/meshes/manipulation/jaco/visual/arm_half_2.dae</uri>
          </mesh>
        </geometry>
        <material>
          <script>
            <uri>__default__</uri>
            <name>__default__</name>
          </script>
        </material>
      </visual>
      <gravity>1</gravity>
      <velocity_decay/>
      <self_collide>0</self_collide>
    </link>
    <joint name='right_arm_half_joint' type='revolute'>
      <child>right_arm_half_2_link</child>
      <parent>right_arm_half_1_link</parent>
      <axis>
        <xyz>-1 -0 -0</xyz>
        <limit>
          <lower>-3.14159</lower>
          <upper>3.14159</upper>
          <effort>30000.5</effort>
          <velocity>0.69115</velocity>
        </limit>
        <dynamics>
          <damping>0.01</damping>
          <friction>0</friction>
          <spring_reference>0</spring_reference>
          <spring_stiffness>0</spring_stiffness>
        </dynamics>
        <use_parent_model_frame>1</use_parent_model_frame>
      </axis>
    </joint>
    <link name='right_forearm_link'>
      <pose frame=''>0.617355 -0.13335 0.279994 -3.14159 0 1.5708</pose>
      <inertial>
        <pose frame=''>0 0.081 -0.0086 0 -0 0</pose>
        <mass>0.674254</mass>
        <inertia>
          <ixx>0.005453</ixx>
          <ixy>3e-06</ixy>
          <ixz>0</ixz>
          <iyy>0.000305</iyy>
          <iyz>8.7e-05</iyz>
          <izz>0.005578</izz>
        </inertia>
      </inertial>
      <collision name='right_forearm_link_collision'>
        <pose frame=''>0 0 0 0 -0 0</pose>
        <geometry>
          <mesh>
            <scale>1 1 1</scale>
            <uri>model://movo_description/meshes/manipulation/jaco/collision/forearm_7dof.stl</uri>
          </mesh>
        </geometry>
      </collision>
      <visual name='right_forearm_link_visual'>
        <pose frame=''>0 0 0 0 -0 0</pose>
        <geometry>
          <mesh>
            <scale>1 1 1</scale>
            <uri>model://movo_description/meshes/manipulation/jaco/visual/forearm_7dof.dae</uri>
          </mesh>
        </geometry>
      </visual>
    </link>
    <joint name='right_elbow_joint' type='revolute'>
      <child>right_forearm_link</child>
      <parent>right_arm_half_2_link</parent>
      <axis>
        <xyz>-0 -0 -1</xyz>
        <limit>
          <lower>-2.809</lower>
          <upper>2.809</upper>
          <effort>18000</effort>
          <velocity>0.69115</velocity>
        </limit>
        <dynamics>
          <damping>0.01</damping>
          <friction>0</friction>
          <spring_reference>0</spring_reference>
          <spring_stiffness>0</spring_stiffness>
        </dynamics>
        <use_parent_model_frame>1</use_parent_model_frame>
      </axis>
    </joint>
    <link name='right_wrist_spherical_1_link'>
      <pose frame=''>0.824655 -0.13335 0.291394 1.5708 -0 -1.5708</pose>
      <inertial>
        <pose frame=''>0 0.002885 -0.054193 0 -0 0</pose>
        <mass>0.463</mass>
        <inertia>
          <ixx>0.000392</ixx>
          <ixy>0</ixy>
          <ixz>0</ixz>
          <iyy>0.000347</iyy>
          <iyz>0.000101</iyz>
          <izz>0.000233</izz>
        </inertia>
      </inertial>
      <collision name='right_wrist_spherical_1_link_collision'>
        <pose frame=''>0 0 0 0 -0 0</pose>
        <geometry>
          <mesh>
            <scale>1 1 1</scale>
            <uri>model://movo_description/meshes/manipulation/jaco/collision/wrist_spherical_1.stl</uri>
          </mesh>
        </geometry>
        <surface>
          <contact>
            <ode>
              <kp>1e+06</kp>
              <kd>100</kd>
              <max_vel>100</max_vel>
              <min_depth>0.001</min_depth>
            </ode>
          </contact>
          <friction>
            <ode>
              <mu>1</mu>
              <mu2>1</mu2>
            </ode>
          </friction>
        </surface>
      </collision>
      <visual name='right_wrist_spherical_1_link_visual'>
        <pose frame=''>0 0 0 0 -0 0</pose>
        <geometry>
          <mesh>
            <scale>1 1 1</scale>
            <uri>model://movo_description/meshes/manipulation/jaco/visual/wrist_spherical_1.dae</uri>
          </mesh>
        </geometry>
        <material>
          <script>
            <uri>__default__</uri>
            <name>__default__</name>
          </script>
        </material>
      </visual>
      <gravity>1</gravity>
      <velocity_decay/>
      <self_collide>0</self_collide>
    </link>
    <joint name='right_wrist_spherical_1_joint' type='revolute'>
      <child>right_wrist_spherical_1_link</child>
      <parent>right_forearm_link</parent>
      <axis>
        <xyz>-1 -0 0</xyz>
        <limit>
          <lower>-3.14159</lower>
          <upper>3.14159</upper>
          <effort>60000.8</effort>
          <velocity>0.921534</velocity>
        </limit>
        <dynamics>
          <damping>0.01</damping>
          <friction>0</friction>
          <spring_reference>0</spring_reference>
          <spring_stiffness>0</spring_stiffness>
        </dynamics>
        <use_parent_model_frame>1</use_parent_model_frame>
      </axis>
    </joint>
    <link name='right_wrist_spherical_2_link'>
      <pose frame=''>0.928405 -0.13335 0.291394 -0 -0 -1.5708</pose>
      <inertial>
        <pose frame=''>0 0.049721 -0.002856 0 -0 0</pose>
        <mass>0.463</mass>
        <inertia>
          <ixx>0.000392</ixx>
          <ixy>0</ixy>
          <ixz>0</ixz>
          <iyy>0.000347</iyy>
          <iyz>0.000101</iyz>
          <izz>0.000233</izz>
        </inertia>
      </inertial>
      <collision name='right_wrist_spherical_2_link_collision'>
        <pose frame=''>0 0 0 0 -0 0</pose>
        <geometry>
          <mesh>
            <scale>1 1 1</scale>
            <uri>model://movo_description/meshes/manipulation/jaco/collision/wrist_spherical_2.stl</uri>
          </mesh>
        </geometry>
        <surface>
          <contact>
            <ode>
              <kp>1e+06</kp>
              <kd>100</kd>
              <max_vel>100</max_vel>
              <min_depth>0.001</min_depth>
            </ode>
          </contact>
          <friction>
            <ode>
              <mu>1</mu>
              <mu2>1</mu2>
            </ode>
          </friction>
        </surface>
      </collision>
      <visual name='right_wrist_spherical_2_link_visual'>
        <pose frame=''>0 0 0 0 -0 0</pose>
        <geometry>
          <mesh>
            <scale>1 1 1</scale>
            <uri>model://movo_description/meshes/manipulation/jaco/visual/wrist_spherical_2.dae</uri>
          </mesh>
        </geometry>
        <material>
          <script>
            <uri>__default__</uri>
            <name>__default__</name>
          </script>
        </material>
      </visual>
      <gravity>1</gravity>
      <velocity_decay/>
      <self_collide>0</self_collide>
    </link>
    <joint name='right_wrist_spherical_2_joint' type='revolute'>
      <child>right_wrist_spherical_2_link</child>
      <parent>right_wrist_spherical_1_link</parent>
      <axis>
        <xyz>0 0 1</xyz>
        <limit>
          <lower>-2.78</lower>
          <upper>2.78</upper>
          <effort>60000.8</effort>
          <velocity>0.921534</velocity>
        </limit>
        <dynamics>
          <damping>0.01</damping>
          <friction>0</friction>
          <spring_reference>0</spring_reference>
          <spring_stiffness>0</spring_stiffness>
        </dynamics>
        <use_parent_model_frame>1</use_parent_model_frame>
      </axis>
    </joint>
    <link name='right_wrist_3_link'>
      <pose frame=''>1.03215 -0.13335 0.291394 -1.5708 0 1.5708</pose>
      <inertial>
        <pose frame=''>-0.000152 -0.004169 -0.09596 0 -0 0</pose>
        <mass>0.990094</mass>
        <inertia>
          <ixx>0.00425431</ixx>
          <ixy>6.65278e-07</ixy>
          <ixz>-1.49586e-05</ixz>
          <iyy>0.00411121</iyy>
          <iyz>0.000122735</iyz>
          <izz>0.000899307</izz>
        </inertia>
      </inertial>
      <collision name='right_wrist_3_link_collision'>
        <pose frame=''>0 0 0 0 -0 0</pose>
        <geometry>
          <mesh>
            <scale>1 1 1</scale>
            <uri>model://movo_description/meshes/manipulation/jaco/collision/kinova_actuator_gearing.stl</uri>
          </mesh>
        </geometry>
        <surface>
          <contact>
            <ode>
              <kp>1e+06</kp>
              <kd>100</kd>
              <max_vel>100</max_vel>
              <min_depth>0.001</min_depth>
            </ode>
          </contact>
          <friction>
            <ode>
              <mu>1</mu>
              <mu2>1</mu2>
            </ode>
          </friction>
        </surface>
      </collision>
      <collision name='right_wrist_3_link_fixed_joint_lump__right_gripper_base_link_collision_1'>
        <pose frame=''>-0 0 0 0 -0 0</pose>
        <geometry>
          <mesh>
            <scale>1 1 1</scale>
            <uri>model://movo_description/meshes/manipulation/kinova_grippers/collision/kg3_base_link.stl</uri>
          </mesh>
        </geometry>
        <surface>
          <contact>
            <ode>
              <kp>1e+06</kp>
              <kd>1</kd>
              <max_vel>0</max_vel>
              <min_depth>0.0001</min_depth>
            </ode>
          </contact>
          <friction>
            <ode>
              <mu>0.8</mu>
              <mu2>0.8</mu2>
            </ode>
          </friction>
        </surface>
      </collision>
      <visual name='right_wrist_3_link_visual'>
        <pose frame=''>0 0 0 0 -0 0</pose>
        <geometry>
          <mesh>
            <scale>1 1 1</scale>
            <uri>model://movo_description/meshes/manipulation/jaco/visual/kinova_actuator_gearing.dae</uri>
          </mesh>
        </geometry>
        <material>
          <script>
            <uri>__default__</uri>
            <name>__default__</name>
          </script>
        </material>
      </visual>
      <visual name='right_wrist_3_link_fixed_joint_lump__right_gripper_base_link_visual_1'>
        <pose frame=''>-0 0 0 0 -0 0</pose>
        <geometry>
          <mesh>
            <scale>1 1 1</scale>
            <uri>model://movo_description/meshes/manipulation/kinova_grippers/visual/kg3_base_link.dae</uri>
          </mesh>
        </geometry>
        <material>
          <script>
            <uri>__default__</uri>
            <name>__default__</name>
          </script>
        </material>
      </visual>
      <velocity_decay/>
      <gravity>1</gravity>
      <velocity_decay/>
      <self_collide>0</self_collide>
    </link>
    <joint name='right_wrist_3_joint' type='revolute'>
      <child>right_wrist_3_link</child>
      <parent>right_wrist_spherical_2_link</parent>
      <axis>
        <xyz>-1 -0 -0</xyz>
        <limit>
          <lower>-3.14159</lower>
          <upper>3.14159</upper>
          <effort>60000.8</effort>
          <velocity>0.921534</velocity>
        </limit>
        <dynamics>
          <damping>0.01</damping>
          <friction>0</friction>
          <spring_reference>0</spring_reference>
          <spring_stiffness>0</spring_stiffness>
        </dynamics>
        <use_parent_model_frame>1</use_parent_model_frame>
      </axis>
    </joint>
    <link name='right_gripper_finger1_knuckle_link'>
      <pose frame=''>1.14679 -0.136145 0.260076 3.08956 -1.39126 -1.62279</pose>
      <inertial>
        <pose frame=''>-0.028253 -0.032416 0 0 -0 0</pose>
        <mass>0.021817</mass>
        <inertia>
          <ixx>9.39482e-06</ixx>
          <ixy>-1.3461e-06</ixy>
          <ixz>0</ixz>
          <iyy>4.07539e-06</iyy>
          <iyz>0</iyz>
          <izz>1.14702e-05</izz>
        </inertia>
      </inertial>
      <collision name='right_gripper_finger1_knuckle_link_collision'>
        <pose frame=''>0 0 0 0 -0 0</pose>
        <geometry>
          <mesh>
            <scale>1 1 1</scale>
            <uri>model://movo_description/meshes/manipulation/kinova_grippers/collision/finger_knuckle.stl</uri>
          </mesh>
        </geometry>
        <surface>
          <contact>
            <ode>
              <kp>1e+06</kp>
              <kd>1</kd>
              <max_vel>0</max_vel>
              <min_depth>0.0001</min_depth>
            </ode>
          </contact>
          <friction>
            <ode>
              <mu>0.8</mu>
              <mu2>0.8</mu2>
            </ode>
          </friction>
        </surface>
      </collision>
      <collision name='right_gripper_finger1_knuckle_link_fixed_joint_lump__right_gripper_finger1_finger_tip_link_collision_1'>
        <pose frame=''>-0.024598 -0.036051 0 0 -0 0</pose>
        <geometry>
          <mesh>
            <scale>1 1 1</scale>
            <uri>model://movo_description/meshes/manipulation/kinova_grippers/collision/finger_tip.stl</uri>
          </mesh>
        </geometry>
        <surface>
          <contact>
            <ode>
              <kp>1e+06</kp>
              <kd>1</kd>
              <max_vel>0</max_vel>
              <min_depth>0.0001</min_depth>
            </ode>
          </contact>
          <friction>
            <ode>
              <mu>0.8</mu>
              <mu2>0.8</mu2>
            </ode>
          </friction>
        </surface>
      </collision>
      <visual name='right_gripper_finger1_knuckle_link_visual'>
        <pose frame=''>0 0 0 0 -0 0</pose>
        <geometry>
          <mesh>
            <scale>1 1 1</scale>
            <uri>model://movo_description/meshes/manipulation/kinova_grippers/visual/finger_knuckle.dae</uri>
          </mesh>
        </geometry>
        <material>
          <script>
            <uri>__default__</uri>
            <name>__default__</name>
          </script>
        </material>
      </visual>
      <visual name='right_gripper_finger1_knuckle_link_fixed_joint_lump__right_gripper_finger1_finger_tip_link_visual_1'>
        <pose frame=''>-0.024598 -0.036051 0 0 -0 0</pose>
        <geometry>
          <mesh>
            <scale>1 1 1</scale>
            <uri>model://movo_description/meshes/manipulation/kinova_grippers/visual/finger_tip.dae</uri>
          </mesh>
        </geometry>
        <material>
          <script>
            <uri>__default__</uri>
            <name>__default__</name>
          </script>
        </material>
      </visual>
      <velocity_decay/>
      <gravity>1</gravity>
      <velocity_decay/>
      <self_collide>0</self_collide>
    </link>
    <joint name='right_gripper_finger1_joint' type='revolute'>
      <child>right_gripper_finger1_knuckle_link</child>
      <parent>right_wrist_3_link</parent>
      <axis>
        <xyz>-0.103009 -0.978563 -0.178336</xyz>
        <limit>
          <lower>0</lower>
          <upper>0.986111</upper>
          <effort>3</effort>
          <velocity>1</velocity>
        </limit>
        <dynamics>
          <spring_reference>0</spring_reference>
          <spring_stiffness>0</spring_stiffness>
        </dynamics>
        <use_parent_model_frame>1</use_parent_model_frame>
      </axis>
    </joint>
    <link name='right_gripper_finger2_knuckle_link'>
      <pose frame=''>1.14686 -0.111061 0.318647 3.14159 1.38609 -1.5708</pose>
      <inertial>
        <pose frame=''>-0.028253 -0.032416 0 0 -0 0</pose>
        <mass>0.021817</mass>
        <inertia>
          <ixx>9.39482e-06</ixx>
          <ixy>-1.3461e-06</ixy>
          <ixz>0</ixz>
          <iyy>4.07539e-06</iyy>
          <iyz>0</iyz>
          <izz>1.14702e-05</izz>
        </inertia>
      </inertial>
      <collision name='right_gripper_finger2_knuckle_link_collision'>
        <pose frame=''>0 0 0 0 -0 0</pose>
        <geometry>
          <mesh>
            <scale>1 1 1</scale>
            <uri>model://movo_description/meshes/manipulation/kinova_grippers/collision/finger_knuckle.stl</uri>
          </mesh>
        </geometry>
        <surface>
          <contact>
            <ode>
              <kp>1e+06</kp>
              <kd>1</kd>
              <max_vel>0</max_vel>
              <min_depth>0.0001</min_depth>
            </ode>
          </contact>
          <friction>
            <ode>
              <mu>0.8</mu>
              <mu2>0.8</mu2>
            </ode>
          </friction>
        </surface>
      </collision>
      <collision name='right_gripper_finger2_knuckle_link_fixed_joint_lump__right_gripper_finger2_finger_tip_link_collision_1'>
        <pose frame=''>-0.024598 -0.036051 0 0 -0 0</pose>
        <geometry>
          <mesh>
            <scale>1 1 1</scale>
            <uri>model://movo_description/meshes/manipulation/kinova_grippers/collision/finger_tip.stl</uri>
          </mesh>
        </geometry>
        <surface>
          <contact>
            <ode>
              <kp>1e+06</kp>
              <kd>1</kd>
              <max_vel>0</max_vel>
              <min_depth>0.0001</min_depth>
            </ode>
          </contact>
          <friction>
            <ode>
              <mu>0.8</mu>
              <mu2>0.8</mu2>
            </ode>
          </friction>
        </surface>
      </collision>
      <visual name='right_gripper_finger2_knuckle_link_visual'>
        <pose frame=''>0 0 0 0 -0 0</pose>
        <geometry>
          <mesh>
            <scale>1 1 1</scale>
            <uri>model://movo_description/meshes/manipulation/kinova_grippers/visual/finger_knuckle.dae</uri>
          </mesh>
        </geometry>
        <material>
          <script>
            <uri>__default__</uri>
            <name>__default__</name>
          </script>
        </material>
      </visual>
      <visual name='right_gripper_finger2_knuckle_link_fixed_joint_lump__right_gripper_finger2_finger_tip_link_visual_1'>
        <pose frame=''>-0.024598 -0.036051 0 0 -0 0</pose>
        <geometry>
          <mesh>
            <scale>1 1 1</scale>
            <uri>model://movo_description/meshes/manipulation/kinova_grippers/visual/finger_tip.dae</uri>
          </mesh>
        </geometry>
        <material>
          <script>
            <uri>__default__</uri>
            <name>__default__</name>
          </script>
        </material>
      </visual>
      <velocity_decay/>
      <gravity>1</gravity>
      <velocity_decay/>
      <self_collide>0</self_collide>
    </link>
    <joint name='right_gripper_finger2_joint' type='revolute'>
      <child>right_gripper_finger2_knuckle_link</child>
      <parent>right_wrist_3_link</parent>
      <axis>
        <xyz>-0 0.982991 -0.183655</xyz>
        <limit>
          <lower>0</lower>
          <upper>0.986111</upper>
          <effort>3</effort>
          <velocity>1</velocity>
        </limit>
        <dynamics>
          <spring_reference>0</spring_reference>
          <spring_stiffness>0</spring_stiffness>
        </dynamics>
        <use_parent_model_frame>1</use_parent_model_frame>
      </axis>
    </joint>
    <link name='right_gripper_finger3_knuckle_link'>
      <pose frame=''>1.14688 -0.155634 0.318617 0 1.3861 1.5708</pose>
      <inertial>
        <pose frame=''>-0.028253 -0.032416 0 0 -0 0</pose>
        <mass>0.021817</mass>
        <inertia>
          <ixx>9.39482e-06</ixx>
          <ixy>-1.3461e-06</ixy>
          <ixz>0</ixz>
          <iyy>4.07539e-06</iyy>
          <iyz>0</iyz>
          <izz>1.14702e-05</izz>
        </inertia>
      </inertial>
      <collision name='right_gripper_finger3_knuckle_link_collision'>
        <pose frame=''>0 0 0 0 -0 0</pose>
        <geometry>
          <mesh>
            <scale>1 1 1</scale>
            <uri>model://movo_description/meshes/manipulation/kinova_grippers/collision/finger_knuckle.stl</uri>
          </mesh>
        </geometry>
        <surface>
          <contact>
            <ode>
              <kp>1e+06</kp>
              <kd>1</kd>
              <max_vel>0</max_vel>
              <min_depth>0.0001</min_depth>
            </ode>
          </contact>
          <friction>
            <ode>
              <mu>0.8</mu>
              <mu2>0.8</mu2>
            </ode>
          </friction>
        </surface>
      </collision>
      <collision name='right_gripper_finger3_knuckle_link_fixed_joint_lump__right_gripper_finger3_finger_tip_link_collision_1'>
        <pose frame=''>-0.024598 -0.036051 0 0 -0 0</pose>
        <geometry>
          <mesh>
            <scale>1 1 1</scale>
            <uri>model://movo_description/meshes/manipulation/kinova_grippers/collision/finger_tip.stl</uri>
          </mesh>
        </geometry>
        <surface>
          <contact>
            <ode>
              <kp>1e+06</kp>
              <kd>1</kd>
              <max_vel>0</max_vel>
              <min_depth>0.0001</min_depth>
            </ode>
          </contact>
          <friction>
            <ode>
              <mu>0.8</mu>
              <mu2>0.8</mu2>
            </ode>
          </friction>
        </surface>
      </collision>
      <visual name='right_gripper_finger3_knuckle_link_visual'>
        <pose frame=''>0 0 0 0 -0 0</pose>
        <geometry>
          <mesh>
            <scale>1 1 1</scale>
            <uri>model://movo_description/meshes/manipulation/kinova_grippers/visual/finger_knuckle.dae</uri>
          </mesh>
        </geometry>
        <material>
          <script>
            <uri>__default__</uri>
            <name>__default__</name>
          </script>
        </material>
      </visual>
      <visual name='right_gripper_finger3_knuckle_link_fixed_joint_lump__right_gripper_finger3_finger_tip_link_visual_1'>
        <pose frame=''>-0.024598 -0.036051 0 0 -0 0</pose>
        <geometry>
          <mesh>
            <scale>1 1 1</scale>
            <uri>model://movo_description/meshes/manipulation/kinova_grippers/visual/finger_tip.dae</uri>
          </mesh>
        </geometry>
        <material>
          <script>
            <uri>__default__</uri>
            <name>__default__</name>
          </script>
        </material>
      </visual>
      <velocity_decay/>
      <gravity>1</gravity>
      <velocity_decay/>
      <self_collide>0</self_collide>
    </link>
    <joint name='right_gripper_finger3_joint' type='revolute'>
      <child>right_gripper_finger3_knuckle_link</child>
      <parent>right_wrist_3_link</parent>
      <axis>
        <xyz>-0 0.982992 0.183648</xyz>
        <limit>
          <lower>0</lower>
          <upper>0.986111</upper>
          <effort>3</effort>
          <velocity>1</velocity>
        </limit>
        <dynamics>
          <spring_reference>0</spring_reference>
          <spring_stiffness>0</spring_stiffness>
        </dynamics>
        <use_parent_model_frame>1</use_parent_model_frame>
      </axis>
    </joint>
    <plugin name='gazebo_ros_control' filename='libgazebo_ros_control.so'>
      <robotNamespace>/</robotNamespace>
    </plugin>
    <plugin name='object_controller' filename='libgazebo_ros_force_based_move.so'>
      <robotNamespace>/</robotNamespace>
      <commandTopic>/movo/cmd_vel</commandTopic>
      <odometryTopic>/movo/odometry/wheel_odometry</odometryTopic>
      <odometryFrame>odom</odometryFrame>
      <odometryRate>100.0</odometryRate>
      <cmdVelTimeOut>0.2</cmdVelTimeOut>
      <robotBaseFrame>base_link</robotBaseFrame>
      <publishOdometryTf>0</publishOdometryTf>
      <yaw_velocity_p_gain>500.0</yaw_velocity_p_gain>
      <x_velocity_p_gain>10000.0</x_velocity_p_gain>
      <y_velocity_p_gain>10000.0</y_velocity_p_gain>
    </plugin>
    <plugin name='gazebo_ros_p3d' filename='libgazebo_ros_p3d.so'>
      <bodyName>base_link</bodyName>
      <topicName>ground_truth_odom</topicName>
      <alwaysOn>true</alwaysOn>
      <updateRate>100.0</updateRate>
    </plugin>
    <plugin name='right_mimic_finger_1_2' filename='libroboticsgroup_gazebo_mimic_joint_plugin.so'>
      <joint>right_gripper_finger1_joint</joint>
      <mimicJoint>right_gripper_finger2_joint</mimicJoint>
    </plugin>
    <plugin name='right_mimic_finger_1_3' filename='libroboticsgroup_gazebo_mimic_joint_plugin.so'>
      <joint>right_gripper_finger1_joint</joint>
      <mimicJoint>right_gripper_finger3_joint</mimicJoint>
    </plugin>
    <plugin name='gazebo_right_grasp_fix' filename='libgazebo_grasp_fix.so'>
      <arm>
        <arm_name>right_arm</arm_name>
        <palm_link>right_wrist_3_link</palm_link>
        <gripper_link>right_gripper_finger1_knuckle_link</gripper_link>
        <gripper_link>right_gripper_finger2_knuckle_link</gripper_link>
        <gripper_link>right_gripper_finger3_knuckle_link</gripper_link>
      </arm>
      <forces_angle_tolerance>100</forces_angle_tolerance>
      <update_rate>50</update_rate>
      <grip_count_threshold>1</grip_count_threshold>
      <max_grip_count>8</max_grip_count>
      <release_tolerance>0.006</release_tolerance>
      <disable_collisions_on_attach>true</disable_collisions_on_attach>
      <contact_topic>right_gripper/contacts</contact_topic>
    </plugin>
    <static>0</static>
    <plugin name='gazebo_left_grasp_fix' filename='libgazebo_grasp_fix.so'>
      <arm>
        <arm_name>left_arm</arm_name>
        <palm_link>left_wrist_3_link</palm_link>
        <gripper_link>left_gripper_finger1_knuckle_link</gripper_link>
        <gripper_link>left_gripper_finger2_knuckle_link</gripper_link>
        <gripper_link>left_gripper_finger3_knuckle_link</gripper_link>
      </arm>
      <forces_angle_tolerance>100</forces_angle_tolerance>
      <update_rate>50</update_rate>
      <grip_count_threshold>1</grip_count_threshold>
      <max_grip_count>8</max_grip_count>
      <release_tolerance>0.006</release_tolerance>
      <disable_collisions_on_attach>true</disable_collisions_on_attach>
      <contact_topic>left_gripper/contacts</contact_topic>
    </plugin>
  </model>
</sdf>
